{"uuid": "9d8d70f0-461a-48fe-bec0-e56f9f0fa9bf", "children": ["236ecd86-01f8-475b-9137-cdd509aa4c3b"], "befores": [{"name": "driver", "status": "broken", "statusDetails": {"message": "selenium.common.exceptions.WebDriverException: Message: Service /root/.cache/selenium/chromedriver/linux64/116.0.5845.96/chromedriver unexpectedly exited. Status code was: 255\n\n", "trace": "  File \"/usr/local/lib/python3.9/site-packages/pluggy/_callers.py\", line 80, in _multicall\n    res = hook_impl.function(*args)\n  File \"/usr/local/lib/python3.9/site-packages/_pytest/fixtures.py\", line 1123, in pytest_fixture_setup\n    result = call_fixture_func(fixturefunc, request, kwargs)\n  File \"/usr/local/lib/python3.9/site-packages/_pytest/fixtures.py\", line 895, in call_fixture_func\n    fixture_result = next(generator)\n  File \"/app/Test_1.py\", line 10, in driver\n    driver = webdriver.Chrome()\n  File \"/usr/local/lib/python3.9/site-packages/selenium/webdriver/chrome/webdriver.py\", line 45, in __init__\n    super().__init__(\n  File \"/usr/local/lib/python3.9/site-packages/selenium/webdriver/chromium/webdriver.py\", line 53, in __init__\n    self.service.start()\n  File \"/usr/local/lib/python3.9/site-packages/selenium/webdriver/common/service.py\", line 109, in start\n    self.assert_process_still_running()\n  File \"/usr/local/lib/python3.9/site-packages/selenium/webdriver/common/service.py\", line 122, in assert_process_still_running\n    raise WebDriverException(f\"Service {self._path} unexpectedly exited. Status code was: {return_code}\")\n"}, "start": 1692626575359, "stop": 1692626866779}], "start": 1692626575358, "stop": 1692626866858}